Workbook

Sheet INF. DISTRITAL
A1: INFORME DE FINANZAS IGLESIA DEL NAZARENO "JUAN NOE"
A2: DISTRITO NORTE DE CHILE | H2: OCTUBRE | I2: 2025
A3: SALDO MES PASADO:SEPTIEMBRE | E3: DINERO EGRESADO:
A4: OTROS MINISTERIOS | C4: 2236439 | E4: POR IGLESIA LOCAL:
A5: IGLESIA | C5: 1739396 | E5: S. | F5: 1 | G5: SOSTEN PASTORAL | H5: =IGLESIA!H13 -> 550000
A6: D.N.I. | C6: 271633 | E6: S. | F6: 2 | G6: VARIOS IGLESIA LOCAL | H6: =IGLESIA!J28 -> 167833
A7: J.N.I. | C7: 32769 | E7: S. | F7: 3 | G7: PRES. DISTRITAL 10% | H7: =D15*10% -> 0
A8: M.N.I. | C8: 300996 | E8: S. | F8: 4 | G8: PRES. EDUCACIONAL 3% | H8: =D15*3% -> 0
A9: Total Saldo mes Pasado | D9: =SUM(C4:C8) -> 4581233 | E9: S. | F9: 5 | G9: PRES. EVANGELISMO 2% | H9: =D15*2% -> 0
A10: POR IGLESIA LOCAL: | E10: S. | F10: 6 | G10: CENTRO DE MINISTERIOS | H10: 0
A11: 1 | B11: OFRENDAS | C11: 0 | E11: S. | F11: 7 | G11: JUBILACION | H11: 4000
A12: 2 | B12: DIEZMOS | C12: 0 | E12: S. | F12: 8 | G12: COCE | H12: 300
A13: 3 | B13: ESPECIALES | E13: S. | F13: 9 | G13: FONDO ASM. GENERAL | H13: 0
C14: 0 | E14: S. | F14: 10 | G14: FONDO DE CONTINGENCIA | H14: 3000
B15: Total entradas iglesia | D15: =SUM(C11:C12) -> 0 | G15: Total gastos iglesia | I15: =SUM(H5:H14) -> 725133
A16: POR OTROS MINISTERIOS: | G16: Total Gastos otros ministerios
A17: 5 | B17: COMPASIÓN | C17: =D15*2%+D17 -> 0 | E17: S. | F17: 11 | G17: MAM
A18: 6 | B18: ADULTO MAYOR | E18: S. | F18: 12 | G18: PROYECTO
A19: 7 | B19: MAM | E19: S. | F19: 13 | G19: ADULTO MAYOR
A20: 8 | B20: ORACIÓN | E20: S. | F20: 14 | G20: ORACION
A21: 9 | B21: PROYECTOS | E21: S. | F21: 16 | G21: ALABANZA
A22: 10 | B22: EVANGELISMO | C22: =D15*2%+D22 -> 0 | E22: S. | F22: 17 | G22: EVANGELISMO
A23: 11 | B23: AHORRO | C23: =D15*4% -> 0 | E23: S. | F23: 18
A24: 12 | B24: alabanza | C24: 100000 | E24: S. | F24: 19
A25: 13 | E25: S. | F25: 20
A26: 17. | E26: Total otros minsiterios | I26: =SUM(H17:H25) -> 0
A27: 18 | E27: POR D.N.I. :
A28: Total otros ministerios | D28: =SUM(C17:C27) -> 100000 | E28: S. | F28: 19 | G28: GASTOS LOCALES
A29: POR D.N.I. : | E29: S. | F29: 21 | G29: CUOTA DISTRITAL | H29: 2750
A30: 19 | B30: OFRENDAS | C30: 0 | E30: S. | F30: 22 | G30: COCE | H30: 300
A31: Total Entradas D.N.I. | D31: =SUM(C30) -> 0 | E31: Total Gastos del D.N.I. | I31: =SUM(H28:H30) -> 3050
A32: POR J.N.I. : | E32: POR J.N.I.
A33: 20 | B33: OFRENDAS | C33: 0 | E33: S. | F33: 23 | G33: GASTOS LOCALES
A34: Total Entradas J.N.I. | D34: =C33 -> 0 | E34: S. | F34: 25 | G34: CUOTA DISTRITAL | H34: 2750
A35: POR M.N.I. : | E35: S. | F35: 26 | G35: COCE | H35: 300
A36: 21 | B36: OFRENDAS | C36: 0 | E36: Total Gastos de J.N.I. | I36: =SUM(H33:H35) -> 3050
A37: 22 | B37: ORACION Y AYUNO | C37: 0 | E37: POR M.N.I. :
A38: 23 | B38: RESURRECCION | C38: 0 | E38: S. | F38: 27 | G38: GASTOS LOCALES | H38: 20000 | K38: 50.000 para los hermanos feria
A39: 24 | B39: ACCION DE GRACIAS | C39: 0 | E39: S. | F39: 29 | G39: CUOTA DISTRITAL | H39: 2750 | K39: 20.000 cajas organizadora
A40: 25 | B40: CAJA DE ALABASTRO | C40: 0 | E40: S. | F40: 30 | G40: COCE | H40: 300
...

Sheet IGLESIA
A1: INFORME MENSUAL DE LA TESORERIA IGLESIA DEL NAZARENO "JUAN NOE" ARICA
A2: FECHA INCLUIDA: | E2: OCTUBRE | G2: 2025
B3: SALDO
B4: IGLESIA | I4: $ | J4: ='INF. DISTRITAL'!C5 -> 1739396
B5: ENTRADAS IGLESIA
B6: OFRENDAS | G6: $ | H6: ='INF. DISTRITAL'!C11 -> 0
B7: DIEZMOS | G7: $ | H7: ='INF. DISTRITAL'!C12 -> 0
B8: ESPECIALES | G8: $ | H8: ='INF. DISTRITAL'!C13 -> 0
G9: $ | J9: =SUM(H6:H7) -> 0
B10: TOTAL ENTRADA IGLESIA | J10: =SUM(H6:H9) -> 0
B11: SUMA SALDO Y ENTRADA IGLESIA | J11: =J4+J10 -> 1739396
B12: EGRESOS IGLESIA
B13: sueldo pastoral | G13: $ | H13: 550000
B14: Mes por año en cuotas mensuales | G14: $ | H14: 45833
B15: LUZ | G15: $
B16: AGUA | G16: $
B17: Internet | G17: $
B18: Zoom | G18: $
B19: Celular | G19: $ | H19: 12000
G20: $ | L20: Thermo eletrico - 189.970 | N20: dividido en 2 personas
B21: 2 Mesa Peglables | G21: $ | H21: 60000
B22: Thermo Baño | G22: $
B23: ofrenda amor | G23: $ | H23: 50000
G24: $
B25: 4%AHORRO | G25: $ | H25: =J9*4% -> 0
G26: $
G27: $
G28: $ | J28: =SUM(H14:H28) -> 167833
G30: $
B31: prs. Distrital 10% | G31: $ | H31: =J9*10% -> 0
B32: prs. Educacional 3% | G32: $ | H32: =J9*3% -> 0
B33: prs. Evangelismo 2% | G33: $ | H33: =J9*2% -> 0
B34: centro de ministerios | E34: Fijo | G34: $ | H34: 0
B35: jubilacion | E35: Fijo | G35: $ | H35: 4000
B36: campamento coce | E36: Fijo | G36: $ | H36: 300
B37: fondo asamblea general | E37: Fijo | G37: $ | H37: 0
B38: fondo contingencia | E38: Fijo | G38: $ | H38: 3000
B39: EGRESO TOTAL IGLESIA | J39: =SUM(H13:H38) -> 725133
B40: SALDO EN CAJA IGLESIA MES DE | E40: OCTUBRE | F40: 2025 | J40: =J11-J39 -> 1014263
B41: BEATRIZ RIQUELME

Sheet DEPOSITOS
B1: IGLESIA DEL NAZARENO-DISTRITO NORTE CHILE
B2: TESORERIA DISTRITAL
B3: COMPROBANTE PARA DEPOSITOS DISTRITALES
D5: CORRESPONDIENTE DEL MES: | F5: OCTUBRE | H5: 2025
A7: A1 | B7: ADMINISTRACION DISTRITAL (10% diezmos y ofrendas) | G7: $ | H7: ='INF. DISTRITAL'!H7 -> 0
A8: C2 | B8: MINISTERIO ESCUELA DOMINICAL (Cuota $ 2.750) | G8: $ | H8: 2750
A9: C3 | B9: JUVENTUD NAZARENA INTERNACIONAL (Cuota $ 2.750) | G9: $ | H9: 2750
A10: C4 | B10: MISIONES NAZARENAS INTERNACIONAL (Cuota $ 2.750) | G10: $ | H10: 2750
A11: C5 | B11: COMITÉ ORGANIZADOR DE CAMP.Y ENCUENTROS
B12: (Cuota $ 200, IGLESIA, MED, JNI, MNI: TOTAL $ 800) | G12: $ | H12: 1200
A13: C6 | B13: EDUCACION TEOLOGICA (3% Diezmos y Ofrendas) | G13: $ | H13: ='INF. DISTRITAL'!H8 -> 0
A14: C7 | B14: EVANGELISMO (2% Diezmos y Ofrendas) | G14: $ | H14: ='INF. DISTRITAL'!H9 -> 0
A15: C8 | B15: PARA CENTRO DE MINISTERIOS Y DISTRITAL (Según cuota) | G15: $ | H15: 0
A16: C9 | B16: FONDO VIAJE ASAMBLEA 2021 PARA LAICO ($ 5.000) | G16: $ | H16: 0
B17: Fondos Para la Evangelizacion Mundial (Presupuesto General)
A18: D1 | B18: ORACION Y AYUNO | G18: $
A19: D1 | B19: RESURRECCION | G19: $
A20: D1 | B20: ACCION DE GRACIAS | G20: $ | H20: ='INF. DISTRITAL'!C39 -> 0
A21: D1 | B21: OFRENDA DE EVANGELISMO (Sobre mensual FEM) | G21: $ | H21: ='INF. DISTRITAL'!C44 -> 0
B22: Otras Ofrendas Misioneras
A23: D2 | B23: CAJA ALABASTRO | G23: $ | H23: ='INF. DISTRITAL'!C40 -> 0
A24: D3 | B24: TRASMISIONES DE MISION MUNDIAL "TMM" | G24: $
A25: D4 | B25: OTRA | G25: $
A26: H7 | B26: JUBILACION PASTORAL ($4000) | G26: $ | H26: 4000
A27: H8 | B27: PARA CONTINGENCIAS (EMERGENCIA) ($3.000) | G27: $ | H27: 3000
G28: $
F29: TOTAL | G29: $ | H29: =SUM(H7:H28) -> 16450
B31: DEPOSITAR EN CUENTA CORRIENTE N° 105-09198-07 EN EL BANCO DE CHILE ARICA A
B32: NOMBRE DE: IGLESIA DEL NAZARENO EVANGELICA DE CHILE
B33: ENVIAR COPIA DE ESTE COMPROBANTE JUNTO A COPIA DE DEPOSITO E INFORME
B34: MENSUAL DE LA TESORERIA DE LA IGLESIA, A LA TESORERA (o entregar a la persona
B35: encargada).
D36: GLORIA MORALES ZEGARRA
D37: Mail: gloria_046@hotmail.com
D38: Celular 09-1419938
A39: NOMBRE DEL DEPOSITANTE: | D39: Beatriz Riquelme
A40: NOTA: El informe Mensual de TESORERIA debe ser enviado al Superintendente de Distrito, JUNTO AL INFORME
A41: MENSUAL DEL PASTOR.
E44: COLOCAR AQUÍ COPIA DEL RECIBO DE DEPÓSITO
E45: NUMERO DEPÓSITO

Sheet DESGLOSE SALDOS
C1: INFORME MENSUAL DE LA TESORERIA
C2: IGLESIA DEL NAZARENO "JUAN NOE"
E3: ARICA
D5: SALDO OTROS MINISTERIOS
B7: SALDO ANTERIOR | E7: SEPTIEMBRE | F7: 2025 | G7: ='INF. DISTRITAL'!C4 -> 2236439
B8: FECHA INCLUIDA
B10: SALDOS AL 01 de | E10: OCTUBRE | F10: 2025 | G10: =G21 -> 2236439
D12: SALDO ANTERIOR | E12: INGRESOS | F12: EGRESOS | G12: SALDO ACTUAL
B13: Alabanza | D13: 600000 | G13: =D13+E13-F13 -> 600000
B14: MAM | D14: 95723 | G14: =D14+E14-F14 -> 95723
B15: Evangelismo | D15: 47060 | G15: =D15+E15-F15 -> 47060
B16: NAZAKIDS | D16: 4870 | G16: =D16+E16-F16 -> 4870
B17: ahorro iglesia | D17: 1398120 | G17: =D17+E17-F17 -> 1398120
G18: =D18+E18-F18 -> 0
B19: NazArtes | D19: 25790 | G19: =D19+E19-F19 -> 25790
B20: adulto mayor | D20: 64876 | G20: =D20+E20-F20 -> 64876
B21: SALDO TOTAL | G21: =SUM(G13:G20) -> 2236439

Sheet Hoja6
A1: mes
A2: ingresos | B2: ofr. Iglesia | C2: especial Igl. | D2: diezmo | E2: D.N.I. | F2: JNI | G2: MNI | H2: FEM | I2: ENFASIS
A3: semana 1
A4: semana 2
A5: semana 3
A6: semana 4
A7: semana 5
A8: deposito
A9: TOTAL | B9: =SUM(B3:B8) -> 0 | C9: =SUM(C3:C8) -> 0 | D9: =SUM(D3:D8) -> 0 | E9: =SUM(E3:E8) -> 0 | F9: =SUM(F3:F8) -> 0 | G9: =SUM(G3:G8) -> 0 | H9: =SUM(H3:H8) -> 0 | I9: =SUM(I3:I8) -> 0
A13: ingresos | B13: COMPASION | C13: AD. MAYOR | D13: MAM | E13: ORACION | F13: PROYECTO | G13: ALABANZA | H13: COMUNIC. | I13: EVANG.
A14: semana 1
A15: semana 2
A16: semana 3
A17: semana 4
A18: semana5
A19: deposito
A20: TOTAL | B20: =SUM(B14:B19) -> 0 | C20: =SUM(C14:C19) -> 0 | D20: =SUM(D14:D19) -> 0 | E20: =SUM(E14:E19) -> 0 | F20: =SUM(F14:F19) -> 0 | G20: =SUM(G14:G19) -> 0 | H20: =SUM(H14:H19) -> 0 | I20: =SUM(I14:I19) -> 0
A23: egresos | B23: iglesia | C23: jni | D23: MAM | E23: MIEDD | F23: PROYECTO | G23: COMPASION | H23: ADULTO MAYOR | I23: MNI | J23: EVANGE | K23: NAZA KIDD
A24: sueldo pastoral
A25: AFP
A26: BONO
A27: MES POR AÑO
A28: ZOOM
A29: LUZ
A30: TELEFONO
A31: AGUA
A32: asamblea
A34: 2%COMPASION
A35: 2%EVANGELISMO
A36: 4%AHORRO
A42: TOTAL | B42: =SUM(B24:B41) -> 0 | C42: =SUM(C24:C41) -> 0 | D42: =SUM(D24:D41) -> 0 | E42: =SUM(E24:E41) -> 0 | F42: =SUM(F24:F41) -> 0 | G42: =SUM(G24:G41) -> 0 | H42: =SUM(H24:H41) -> 0 | I42: =SUM(I24:I41) -> 0 | ... K42: =SUM(K24:K41) -> 0
